Workbook

Sheet All_Data
A1: Meta Data | H1: Dataset Information | V1: HAR Algorithm/Model Information and Preprocessing Steps | AJ1: Availability
A2: Contribution Area | B2: Article ID | C2: Title | D2: First Author | E2: doi | F2: Date (Month) | G2: Date (Year) | H2: Dataset Name | I2: Data Public? | J2: Dataset Link (if self collected) | K2: Frequency (Hz) | L2: Range (± g) | M2: Device (Name + Brand) | N2: No. Participants | O2: Demographics | P2: Collection Protocol | Q2: Balanced? | R2: No. Activities | S2: Activity Names | T2: Activitiy Definitions | U2: Sensor Location | V2: Base Algorithm or Architecture | W2: Compare Mult. Algs? | X2: Implementation (software/libraries) | Y2: Hand Crafted Features? | Z2: Features | AA2: Window length (s) | AB2: Overlap (%) | AC2: Train/Test Split | AD2: Metrics | AE2: Performance of Wrist Accel Only (See…) | AF2: Class Wise Evaluation | AG2: Performance of Other Sensors (same dataset) | AH2: Performance of same Algorithm on Other Datasets (not neccesarily WAO) | AI2: Trained on a dataset and evaluated on another one | AJ2: Code? | AK2: Code (Link) | AL2: Trained Model Weights (open weight) | AM2: Replicable? | AN2: Why not replicable? (Defs in Sec. 4.3.1) | AO2: Notes on replication | AP2: Reproducible? | AQ2: Why not reproducible? (Defs in Sec. 4.3.1) | AR2: Notes on reproduction
A3: Algorithm Improvement (e.g., architecture or preprocessing) | B3: 66 | C3: A Hybrid Solution for Human Activity Recognition: Application to Wrist-Worn Accelerometry | D3: Manuel Abbas | E3: https://doi.org/10.1109/ICABME47164.2019.8940233 | F3: Oct | G3: 2019 | H3: SC | I3: N/A | K3: 238 | L3: 8 | M3: LSM9DS1 by STMicroelectronics | N3: 10 | O3: 5 M, 5 F, 22-53 yo | P3: Semi- or highly-supervised | Q3: N | R3: 5 | S3: sitting, standing, walking, jogging, stairs | T3: activities derived from (1) walking towards a chair then sitting down, (2) sitting-down after being inactive for a while, (3) standing-up and staying inactive for a while, (4) standing-up then starting walking immediately. | U3: N/A | V3: Linear and quadratic SVM, Random Forest, Artificial Neural Network (ANN) with one hidden layer of 10 neurons (shallow learning) and k-NN (k=5). | W3: Y | X3: N/A | Y3: Y | Z3: See Section III A | AA3: 5 | AB3: 40 | AC3: 10-fold CV | AD3: Accuracy | AE3: Table 1 | AF3: Y | AG3: N | AH3: N | AI3: N | AJ3: N | AL3: N | AM3: N | AN3: IP | AP3: N | AQ3: DNA | AS3: =IF(AND(AP3="N", ISBLANK(AQ3)), "THIS", "") | AU3: Y | AV3: DNA | AW3: IP
B4: 94 | C4: Characterizing Peaks in Acceleration Signals–Application to Physical Activity Detection Using Wearable Sensors | D4: Manuel Abbas | E4: https://doi.org/10.1109/JSEN.2020.3000394 | F4: Jun | G4: 2020 | H4: SC | I4: N/A | K4: 238 | L4: 8 | M4: LSDM9DS1 | N4: 9 | O4: 4 M, 5 F, 24-53 yo (median of 33 yo), 48-80 kg, 158-180 cm | P4: N/A | Q4: N | R4: 4 | S4: C-1, C-2, C-3, C-4 | T4: clapping hands (C-1), waving goodbye, shaking hands (C-2), walking slowly/quickly, going upstairs then downstairs (C-3) and jogging (C-4) | U4: N/A | V4: RF, CNN, their solution (DT + SVM) | W4: Y | X4: N/A | Y4: Y | Z4: "prominence, width, variability and entropy " or "mean, std, skewness, kurtosis, energy of the signal, frequency-domain entropy, interquartile range, root mean square and mean absolute deviation" | AA4: 3 | AB4: 66 | AC4: 10-fold and LOSO CV | AD4: Accuracy | AE4: Table 2 | AF4: Y | AG4: N | AH4: N | AI4: N | AJ4: N | AL4: N | AM4: Y | AP4: N | AQ4: DNA | AS4: =IF(AND(AP4="N", ISBLANK(AQ4)), "THIS", "") | AU4: N | AV4: TTS | AW4: IF
B5: 5 | C5: Daily living activity recognition based on statistical feature quality group selection | D5: Oresti Banos | E5: https://doi.org/10.1016/j.eswa.2012.01.164 | F5: Jul | G5: 2012 | H5: Bao + Intille | I5: Y | K5: 20 | L5: N/A | M5: N/A | N5: N/A | O5: N/A | P5: Semi- or highly-supervised | Q5: N/A | R5: 4 | S5: Walking, sitting and relaxing, standing still and running | T5: N/A | U5: N/A | V5: C4.5 (DT), SVM with RBF kernel, NB | W5: Y | X5: N/A | Y5: Y | Z5: See Sec. 2.2 and 2.3 | AA5: N/A | AB5: N/A | AC5: 10-fold CV | AD5: Accuracy | AE5: Figure 5 | AF5: N | AG5: Y | AH5: Y* (lab + simfl within a single dataset) | AI5: N | AJ5: N | AL5: N | AM5: N | AN5: IS | AP5: N | AQ5: TTS | AS5: =IF(AND(AP5="N", ISBLANK(AQ5)), "THIS", "") | AV5: ANR | AW5: IS
B6: 24 | C6: Significant Features for Human Activity Recognition Using Tri-Axial Accelerometers | D6: Mohamed Bennasar | E6: https://doi.org/10.3390/s22197482 | F6: Oct | G6: 2022 | H6: HHAR | I6: Y | K6: 100, 200 | L6: N/A | M6: Samsung and LG smartwatch | N6: 9 | O6: 25-30 yo | P6: Semi- or highly-supervised | Q6: N | R6: 6 | S6: walking, biking, sitting, ascending stairs, descending stairs and standing | T6: N/A | U6: N/A | V6: SVM (linear kernel), KNN (k=3) | W6: Y | X6: MATLAB | Y6: Y | Z6: See Table 2 | AA6: 2.5 | AB6: N/A | AC6: 5-fold CV | AD6: Accuracy, F1 | AE6: Table 2, 3, 4 | AF6: N | AG6: N | AH6: Y | AI6: N | AJ6: N | AL6: N | AM6: N | AN6: IS | AP6: N | AQ6: TTS | AS6: =IF(AND(AP6="N", ISBLANK(AQ6)), "THIS", "")
H7: PAMAP2 | I7: Y | K7: 100 | L7: N/A | M7: N/A | N7: 9 | O7: 1F, 8M, 24-32 yo | P7: Semi- or highly-supervised | Q7: N | R7: 12 | S7: Lying (6.7%), Sitting (13.06%), Walking (8.2%), Running (3.3%), Cycling (5.73%), Nordic walking (6.48%), Upstairs (4.08%), Downstairs (3.65), vacuum cleaning (6.13%), Ironing (8.31%), Rope jumping (1.92%), Other (transient activities) (32.44%) | T7: N/A | U7: D | AS7: =IF(AND(AP7="N", ISBLANK(AQ7)), "THIS", "")
B8: 25 | C8: Improving Deep Learning for HAR with Shallow LSTMs | D8: Marius Bock | E8: https://doi.org/10.1145/3460421.3480419 | F8: Sep | G8: 2021 | H8: HHAR | I8: Y | K8: 100 | L8: N/A | M8: N/A | N8: 9 | O8: N/A | P8: N/A | Q8: N/A | R8: 6 | S8: Biking, sitting, standing, walking, walking upstairs and downstairs, (null) | T8: N/A | U8: N/A | V8: LSTMS (1 or 2 layered) | W8: Y | X8: PyTorch | Y8: N | AA8: 1 | AB8: 60 | AC8: LOSO CV | AD8: F1, Precision, Recall | AE8: Fig. 2B | AF8: N | AG8: N | AH8: Y | AI8: N | AJ8: Y | AK8: https://github.com/mariusbock/dl-for-har/tree/main | AL8: Y * (there are model weights. Correspondance with the author revealed they do not know what trainings they are the result of.) | AM8: Y | AP8: Y | AS8: =IF(AND(AP8="N", ISBLANK(AQ8)), "THIS", "")
H9: RealWorld HAR | I9: Y | K9: 50 | L9: N/A | M9: N/A | N9: 15 | O9: N/A | P9: N/A | Q9: N/A | R9: 8 | S9: Walking upstairs, walking downstairs, jumping, lying, standing, sitting, running, walking, (null) | T9: N/A | U9: N/A | AS9: =IF(AND(AP9="N", ISBLANK(AQ9)), "THIS", "")
B10: 151 | C10: Handling heterogeneity in Human Activity Recognition data by a compact Long Short Term Memory based deep learning approach | D10: Ahmed Cemiloglu | E10: https://doi.org/10.1016/j.engappai.2025.110788 | F10: Aug | G10: 2025 | H10: HHAR | I10: Y | K10: 100, 200 | L10: N/A | M10: Samsung Galaxy Gear and LG G | N10: 9 | O10: 25-30 yo | P10: Semi- or highly-supervised | Q10: Y (5 min/activity) | R10: 6 | S10: stand, sit, walk, stairsup, stairsdown, bike | T10: N/A | U10: B | V10: LSTM-CNN | W10: Y | X10: TensorFlow/Keras | Y10: N | AA10: 60 | AB10: N/A | AC10: SS. 70/15/15 | AD10: F1, Precision, Recall, Accuracy | AE10: Fig. 4, Table 5 | AF10: Y (Table 5) | AG10: Y | AH10: N | AI10: N | AJ10: N | AL10: N | AM10: N | AN10: IS | AP10: N | AQ10: ANR | AS10: =IF(AND(AP10="N", ISBLANK(AQ10)), "THIS", "")
B11: 59 | C11: Activity classification using a single wrist-worn accelerometer | D11: Saisakul Chernbumroong | E11: https://doi.org/10.1109/SKIMA.2011.6089975 | F11: Sep | G11: 2011 | H11: SC | I11: N/A | K11: 33 | L11: 2 | M11: eZ430-Chronos | N11: 7 | O11: 2 F, 27-35 yo | P11: Semi- or highly-supervised | Q11: N | R11: 5 | S11: Sitting, Standing, Lying, Walking, Running | T11: See Table 2 | U11: ND | V11: DT (C4.5) and ANN | W11: Y | X11: WEKA (DT) | Y11: Y | Z11: See Table 1 | AA11: 3.88 | AB11: 50 | AC11: 5-fold CV (10 runs) | AD11: Accuracy, F1 | AE11: Table IV | AF11: N | AG11: N | AH11: N | AI11: N | AJ11: N | AL11: N | AM11: N | AN11: IP | AO11: NOTE: DT is likely replicable. | AP11: N | AQ11: DNA | AS11: =IF(AND(AP11="N", ISBLANK(AQ11)), "THIS", "")
B12: 39 | C12: Temporal Alignment Improves Feature Quality: An Experiment on Activity Recognition with Accelerometer Data | D12: Hongjun Choi | E12: https://doi.org/10.1109/CVPRW.2018.00075 | F12: Jun | G12: 2018 | H12: SC | I12: N/A | K12: N/A | L12: N/A | M12: GENEActiv sensor | N12: 50 | O12: 18-64 yo | P12: Semi- or highly-supervised | Q12: Y | R12: 7 | S12: Walking (treadmill at 1mph), Walking (treadmill at 4mph), Running (treadmill at 6mph, 5% grade), Seated/folding/stacking laundry, Standing/fidgeting with hand while talking, Hard surface walking holding filled coffee cup, Walking down stairs (5 floors) | T12: N/A | U12: ND | V12: SVM (with RBF kernel) | W12: N | X12: Libsvm toolbox | Y12: 37 | Z12: "Finally, a 37-dimensional feature vector is used and calculated for each window for SVM training and prediction. The final features include: 1) Mean, variance, and root mean square values of the acceleration values on each of Cx, Cy, Cz and CE respectively. 2) Pearson correlation coefficients between all combinations of Cx, Cy, Cz and CE, frequency domain entropy, and the PSD from FFT values. 3) Difference between maximum and minimum accelerations on each axis (dx, dy, dz, dE), and the following 5 features [11]:" | AA12: Varies: 50 samples - 1000 samples | AB12: N/A | AC12: LOSO CV | AD12: Accuracy | AE12: Table 2 | AF12: Y | AG12: N | AH12: N | AI12: N | AJ12: N | AL12: N | AM12: N | AN12: IS | AP12: N | AQ12: DNA | AS12: =IF(AND(AP12="N", ISBLANK(AQ12)), "THIS", "")
B13: 132 | C13: Ensemble Methods for Classification of Physical Activities from Wrist Accelerometry | D13: Aok Kumar Chowdhury | E13: 10.1249/MSS.0000000000001291 | F13: Sept | G13: 2017 | H13: PAMAP2 | I13: Y | K13: 100 | L13: 16 | M13: Colobri IMU | N13: 9 | O13: See Table 1 | P13: Semi- or highly-supervised | Q13: N | R13: 8 (from 12) | S13: lying down, sitting, standing, walking running, cycling, ascending stairs, descending stairs | T13: N/A | U13: D | V13: ensemble method. BDT, KNN, SVM, ANN, WMV, NB cominer, and BKS combiner | W13: Y | X13: Matlab | Y13: Y | Z13: See Sec. Feature Extraction | AA13: 10 | AB13: 50 | AC13: LOSO CV | AD13: F1 | AE13: Tables 2-4 | AF13: Y | AG13: Y | AH13: Y | AI13: N | AJ13: Y | AK13: https://github.com/alokchy04/Decision-Fused-Ensembles-for-PA-Classification-from-Wrist-Worn-Accelerometer | AL13: N | AM13: Y | AP13: Y | AR13: ANN is missing seed, so you may get slightly different results. Also, data is in already generated features. | AS13: =IF(AND(AP13="N", ISBLANK(AQ13)), "THIS", "")
H14: SC | I14: Y* (extracted features) | J14: https://github.com/alokchy04/Decision-Fused-Ensembles-for-PA-Classification-from-Wrist-Worn-Accelerometer/tree/master/FET | K14: 32 | L14: 2 | M14: Empatica E4 | N14: 8 | O14: See Table 1 | P14: Semi- or highly-supervised | Q14: N | R14: 5 | S14: sit or stand still, self-paced comfortable walk, self-paced brisk walk, jogging, and fast-run | T14: N/A | U14: ND | AS14: =IF(AND(AP14="N", ISBLANK(AQ14)), "THIS", "")
H15: SC | I15: Y* (extracted features) | K15: 20 | L15: 6 | M15: ActiGraph GT3X+ | N15: 17 | O15: See Table 1 | P15: Semi- or highly-supervised | Q15: N | R15: 7 | S15: Lying down, sitting (handwriting, computer game), standing with upper body movements (throw and catch, laundry task, floor sweeping), walking (comfortable overground walk, brisk overground walk, brisk treadmill walk), running, basketball, and dance | T15: N/A | U15: ND | AS15: =IF(AND(AP15="N", ISBLANK(AQ15)), "THIS", "")
B16: 155 | C16: Situation identification in smart wearable computing systems based on machine learning and Context Space Theory | D16: Giuseppe D'Aniello | E16: https://doi.org/10.1016/j.inffus.2023.102197 | F16: April | G16: 2024 | H16: Extrasensory | I16: Y | K16: 25 | L16: N/A | M16: N/A | N16: 60 | O16: N/A | P16: Free-living | Q16: N/A | R16: 5 | S16: Sitting, standing, lying down, walking, running | T16: Table 2 | U16: N/A | V16: ANN, NB, KNN, RF, and DT | W16: Y | X16: Python and sci-kit learn | Y16: Y (from the original authors of the dataset) | Z16: "magnitude standard deviation (std), magnitude moment 4, magnitude 75-percentile, magnitude log energy band 2, magnitude log energy band 3, magnitude log energy band 4, mean-x, mean-y, mean-z, std-x, std-y, std-z, direction cosine similarity" | AA16: 20 | AB16: 0 | AC16: 5-fold CV | AD16: Accuracy, F1, Precision, Recall | AE16: Table 5 | AF16: N (they include classwise evaluations just not of wrist only) | AG16: Y | AH16: N | AI16: N | AJ16: Y | AK16: https://github.com/knowmis/SAWCS-Situation-Identification-in-Smart-Wearable-Computing-Systems | AL16: N | AM16: Y | AP16: Y | AS16: =IF(AND(AP16="N", ISBLANK(AQ16)), "THIS", "")
B17: 83 | C17: Comparing Supervised Learning Techniques on the Task of Physical Activity Recognition | D17: Anthony Dalton | E17: https://doi.org/10.1109/TITB.2012.2223823 | F17: Jan | G17: 2013 | H17: SC | I17: N/A | K17: 132 | L17: 6 | M17: N/A | N17: 25 | O17: 10 M, 15 F, mean age: 23.6 (2.41) yo | P17: Free-living | Q17: N | R17: 19 | S17: See Table 1 | T17: See Table 1 | U17: D | V17: C4.5, NB, BayesNet, IB1, IBK, KStar, JRip, SVM, MLP, AdaBoost, AdaBoostM1, Bagging,MultiBoost, Vote (Table IV) | W17: Y | X17: MATLAB and WEKA | Y17: Y | Z17: See Table II | AA17: 1 | AB17: 50 | AC17: LOSO CV | AD17: Kappa | AE17: Table 5 | AF17: N | AG17: Y | AH17: N | AI17: N | AJ17: N | AL17: N | AM17: Y | AP17: N | AQ17: DNA | AS17: =IF(AND(AP17="N", ISBLANK(AQ17)), "THIS", "")
B18: 99 | C18: Recognition of Human Behavior for Assisted Living Using Dictionary Learning Approach | D18: Pubali De | E18: https://doi.org/10.1109/JSEN.2017.2787616 | F18: Dec | G18: 2017 | H18: WHARF | I18: Y | K18: 32 | L18: 3 | M18: N/A | N18: 16 | O18: 11 M, 5 W | P18: N/A | Q18: N/A | R18: 7 | S18: getting up from the bed (GUB), sitting down on a chair (SDC) and standing up from a chair (SUC), reiterated actions (climbing stairs (CS) and walking (WK)) and complex actions (drinking water (DW) and pouring water from glasses (PWG)) | T18: N/A | U18: N/A | V18: K-singular value decomposition (K-SVD) (theirs), SVM, KNN, SRC, CRC-RLS, competing [12] | W18: Y | X18: N/A | Y18: N/A | AA18: N/A | AB18: N/A | AC18: SS. 80/20 | AD18: Accuracy, TN, TP | AE18: Table 1, 3 | AF18: Y | AG18: N | AH18: N | AI18: N | AJ18: N | AL18: N | AM18: N | AN18: IS | AP18: N | AQ18: TTS | AS18: =IF(AND(AP18="N", ISBLANK(AQ18)), "THIS", "")
B19: 46 | C19: Multi-Criteria Analysis of Sensor Reliability for Wearable Human Activity Recognition | D19: Yilin Dong | E19: https://doi.org/10.1109/JSEN.2021.3089579 | F19: Jun | G19: 2021 | H19: MHEALTH | I19: Y | K19: 50 | L19: N/A | M19: N/A | N19: 10 | O19: Diverse profiles (see paper) | P19: Semi- or highly-supervised | Q19: Y | R19: 12 | S19: standing still, sitting and relaxing, lying down, walking, climbing stairs, waist bends forward, frontal elevation of arms, knees bending, cycling, jogging, running, jump front and back | T19: N/A | U19: R | V19: SVM, Hidden conditional random forest (HCRF), and CNN. They propose a fused LSTM (which is not relevant for this review) | W19: Y | X19: MATLAB | Y19: Y for tranditional models | Z19: "hand-crafted features" | AA19: N/A | AB19: N/A | AC19: 10-fold CV (80/20 split within folds) | AD19: Accuracy | AE19: Fig. 7 | AF19: Y | AG19: Y | AH19: N | AI19: N | AJ19: N | AL19: N | AM19: N | AN19: IS | AP19: N | AQ19: TTS | AS19: =IF(AND(AP19="N", ISBLANK(AQ19)), "THIS", "")
B20: 87 | C20: Temporal-channel convolution with self-attention network for human activity recognition using wearable sensors | D20: Ehab Essa | E20: https://doi.org/10.1016/j.knosys.2023.110867 | F20: Oct | G20: 2023 | H20: WHARF | I20: Y | K20: 32 | L20: N/A | M20: N/A | N20: 16 | O20: N/A | P20: Semi- or highly-supervised | Q20: N/A | R20: 14 | S20: Not fully specified, but included activities "such as brushing teeth, sitting down on a chair, eating with a spoon, climbing the stairs, and walking" | T20: N/A | U20: R | V20: LSTM, transformer, CSNET, TCCSNET | W20: Y | X20: TensorFlow/Keras | Y20: N | AA20: N/A | AB20: N/A | AC20: LOSO CV | AD20: Accuracy, F1, Precision, Recall | AE20: Table 5 | AF20: Y | AG20: N | AH20: Y | AI20: N | AJ20: N | AL20: N | AM20: N | AN20: IS | AP20: N | AQ20: ANR | AS20: =IF(AND(AP20="N", ISBLANK(AQ20)), "THIS", "")
B21: 13 | C21: Matched Filter Interpretation of CNN Classifiers with Application to HAR | D21: Mohammed M. Farag | E21: https://doi.org/10.3390/s22208060 | F21: Oct | G21: 2022 | H21: WISDM | I21: Y | K21: 20 | L21: N/A | M21: N/A | N21: 29 | O21: N/A | P21: N/A | Q21: N | R21: 6 | S21: Walking, Upstairs, Downstairs, Sitting, Lying, Jogging | T21: N/A | U21: N/A | V21: MF CNN | W21: N | X21: Keras/Tensorflow | Y21: N | AA21: 2.6 | AB21: 25 | AC21: SS. 64/16/24 | AD21: Accuracy, F1 | AE21: Table 3 | AF21: Y | AG21: Y | AH21: Y | AI21: N | AJ21: N | AL21: N | AM21: Y | AP21: N | AQ21: TTS | AS21: =IF(AND(AP21="N", ISBLANK(AQ21)), "THIS", "")
B22: 14 | C22: AccNet24: A deep learning framework for classifying 24-hour activity behaviours from wrist-worn accelerometer data under free-living environments | D22: Vahid Farrahi | E22: https://doi.org/10.1016/j.ijmedinf.2023.105004 | F22: Apr | G22: 2023 | H22: CAPTURE-24 | I22: Y | K22: 100 | L22: N/A | M22: Axivity AX3 | N22: 151 | O22: 18-91 yo | P22: Free-living | Q22: N | R22: 4 | S22: Sleep, sed, lpa, mvpa | T22: Table 1 | U22: N/A | V22: Balanced RF, ANN, SVM, DT, NB, Acc-Net | W22: Y | X22: MATLAB, pyts package | Y22: Y (when applicable) | Z22: "For each window, we extracted a 112-dimensional feature vector. These features were selected from an extensive list of time and frequency domain features described in previous studies [18,24,25] and are listed in online supplemental Table 1. The extracted features were used as inputs for balanced RF, ANN, SVM, DT, and NB to classify sleep, sedentary behaviour, LPA, and MVPA. " | AA22: 30 | AB22: 0 | AC22: SS. 67/16.5/16.5 | AD22: Accuracy | AE22: Fig. 3 | AF22: Y | AG22: N | AH22: N | AI22: N | AJ22: N | AL22: N | AM22: N | AN22: IP | AP22: N | AQ22: TTS | AS22: =IF(AND(AP22="N", ISBLANK(AQ22)), "THIS", "")
B23: 85 | C23: A Comparative Study on Fitness Activity Recognition | D23: Igor Lopes de Faria | E23: https://doi.org/10.1145/3243082.3267452 | F23: Oct | G23: 2018 | H23: SC | I23: N/A | K23: N/A | L23: N/A | M23: N/A | N23: 4 | O23: 2 M, 2 F, 25-30 yo | P23: Semi- or highly-supervised | Q23: Y | R23: 3 | S23: walking and running on the tread- mill and the dumbbell biceps curl | T23: "The treadmill speed could not be more than seven kilometers per hour and the running speed could not be less than this value. For the exercise of stimulating biceps it was not necessary to use dumbbells, only the execution of the movement, being a choice of the volunteer to use the dumbbells or not." | U23: N/A | V23: KNN, j48, NB, SVM, MLP | W23: Y | X23: R | Y23: Y | Z23: "In the pre-processing phase, we extracted two time-domain features for these sensors: average and standard deviation." | AA23: 2 | AB23: 0 | AC23: 10-fold CV | AD23: Accuracy | AE23: Table 1 | AF23: N | AG23: N | AH23: N | AI23: N | AJ23: N | AL23: N | AM23: N | AN23: IP | AP23: N | AQ23: DNA | AS23: =IF(AND(AP23="N", ISBLANK(AQ23)), "THIS", "")
B24: 7 | C24: Improving Activity Recognition while Reducing Misclassification of Unknown Activities | D24: Andrea Fasciglione | E24: https://doi.org/10.1109/WETICE53228.2021.00039 | F24: Oct | G24: 2021 | H24: SC | I24: N/A | K24: 256 | L24: N/A | M24: N/A | N24: 8 | O24: "Healthy" | P24: N/A | Q24: N/A | R24: 17 | S24: 1. Relaxing on a chair , 7. Brushing Teeth, 13. Downstairs, 2. Keyboard Typing, 8. Sweeping, 14. Walking, 3. Using the Laptop, 9. Vacuuming, 15. Walking Fast, 4. Handwriting, 10. Eating (a soup), 16. Upstairs Fast, 5. Washing Hands, 11. Dusting surface, 17. Upstairs, 6. Washing Face, 12. Rubbing surface | T24: N/A | U24: D | V24: Ensemble method. Five traditional models predicting at once (SVM, DT, RF, KNN, and gaussian NB). Majority of the votes is the final prediction; no majority vote "other" class. | W24: N | X24: N/A | Y24: Y | Z24: "During the features extraction, the sliding window passes over the data and, for each axis (X, Y, Z), different measures are extracted from the data contained in the window: mean, variance, standard deviation, median absolute deviation, percentiles (10Th, 25Th, 75Th, 90Th), obtaining a total of 24 features." | AA24: N/A (Features are extracted from 2s windows with 95% overlap but results are discussed from 5s windows (50 samples). They also investigated multiple window sizes to remove outliers. | AB24: N/A | AC24: SS. 75/25 | AD24: F1 | AE24: Table 2 and 3 | AF24: N | AG24: Y | AH24: N | AI24: N | AJ24: N | AL24: N | AM24: N | AN24: IS | AP24: N | AQ24: DNA | AS24: =IF(AND(AP24="N", ISBLANK(AQ24)), "THIS", "")
B25: 152 | C25: Modelling time-series data generation with diffusion models for triaxial data | D25: Francisco M. Garcia-Moreno | E25: https://doi.org/10.1016/j.asoc.2025.114195 | F25: Jan | G25: 2026 | H25: WISDM | I25: Y | K25: 20 | L25: N/A | M25: N/A | N25: 51 | O25: N/A | P25: Semi- or highly-supervised | Q25: Y (See Table 2) | R25: 5 (a subset of the original 18) | S25: walking, jogging, stairs (ascending + descensing), sitting, and standing | T25: N/A | U25: N/A | V25: Diffusion Models using recurrence plots: VGG-16, ResNet-18, ResNet-34, ResNext-50, InceptionResNetv2 | W25: Y | X25: N/A | Y25: N | AA25: 2.56 (129 samples) | AB25: 0 | AC25: LOTO (leave one trial out) CV and LOSO CV | AD25: Accuracy, F1, Precision, Recall, and Specificity | AE25: Tables 4-11 and Fig. 8+ 9 | AF25: N | AG25: N | AH25: N | AI25: N | AJ25: Y | AK25: https://github.com/crowsonkb/k-diffusion | AL25: N | AM25: Y | AP25: Y | AS25: =IF(AND(AP25="N", ISBLANK(AQ25)), "THIS", "")
B26: 15 | C26: How Accurately Can Your Wrist Device Recognize Daily Activities and Detect Falls? | D26: Martin Gjoreski | E26: https://doi.org/10.3390/s16060800 | F26: May | G26: 2016 | H26: SC (Faculty of Sports) | I26: Y* | J26: Link seems dead. | K26: 40 | L26: 4 | M26: Shimmer 2R | N26: 10 | O26: Avg ave 27.2 (3.1) yo, 8 M, 2 F | P26: Semi- or highly-supervised | Q26: N | R26: 10 | S26: lying (23%), standing (17%), walking (14%), sitting (12%), cycling (10), on all fours (8%), kneeling (6%), running (5%), bending and transition | T26: N/A | U26: R | V26: J48, RF, NB, SVM, KNN | W26: Y | X26: N/A | Y26: Y | Z26: See Table 2 | AA26: 4 | AB26: 50 | AC26: LOSO CV | AD26: Accuracy | AE26: Fig. 7 | AF26: N | AG26: Y | AH26: Y | AI26: N | AJ26: N | AL26: N | AM26: N | AN26: IP | AP26: N | AQ26: ANR | AS26: =IF(AND(AP26="N", ISBLANK(AQ26)), "THIS", "")
H27: SC (JSI) | I27: Y* | J27: Link seems dead. | K27: 50 | L27: 4 | M27: Xsens-MTx inertial sensors | N27: 5 | O27: Healthy, 29.4 (2.1) yo, 4 M, 1 F | P27: Semi- or highly-supervised | Q27: N | R27: 10 | S27: cycling (18%), walking (17%), standing (14%), lying (13%), sitting (11%), running (9%), on all fours (7%), kneeling (5), bending (3.5), and transition (2.5%) | T27: N/A | U27: B | AE27: Fig. 6 | AF27: N | AG27: Y | AH27: Y | AI27: N | AS27: =IF(AND(AP27="N", ISBLANK(AQ27)), "THIS", "")
H28: Opportunity | I28: Y | K28: 30 | L28: N/A | M28: InertiaCube3 | N28: 3 | O28: N/A | P28: Semi- or highly-supervised | Q28: N | R28: 4 | S28: standing (50%), walking (28%), sitting (19%), and lying (3%) | T28: N/A | U28: B | AE28: Fig. 8 | AF28: Y | AG28: N | AH28: Y | AI28: N | AS28: =IF(AND(AP28="N", ISBLANK(AQ28)), "THIS", "")
B29: 31 | C29: Reducing the Impact of Sensor Orientation Variability in Human Activity Recognition Using a Consistent Reference System | D29: Manuel Gil-Martín | E29: https://doi.org/10.3390/s23135845 | F29: Jun | G29: 2023 | H29: PAMAP2 | I29: Y | K29: 100 | L29: N/A | M29: N/A | N29: 9 | O29: N/A | P29: Semi- or highly-supervised | Q29: N | R29: 12 | S29: lying, sitting, standing, walking, running, cycling, Nordic walk, ascending stairs, descending stairs, ironing, vacuum cleaning, and rope jumping | T29: N/A | U29: D | V29: CNN | W29: N | X29: N/A | Y29: N | AA29: 5 | AB29: 20 | AC29: LOSO CV and 10-fold CV by subject | AD29: Accuracy | AE29: Table 3 and 4 | AF29: N | AG29: Y | AH29: Y | AI29: N | AJ29: N | AL29: N | AM29: Y | AP29: N | AQ29: TTS | AR29: NOTE: LOSO may be reproducible. | AS29: =IF(AND(AP29="N", ISBLANK(AQ29)), "THIS", "")
B30: 88 | C30: Towards Learning Discrete Representations via Self-Supervision for Wearables-Based Human Activity Recognition | D30: Harish Haresamudram | E30: https://doi.org/10.3390/s24041238 | F30: Feb | G30: 2024 | H30: HHAR | I30: Y | K30: 50 (downsampled) | L30: N/A | M30: Smartwatches (LG G and Samsung Galaxy Gear) | N30: 9 | O30: N/A | P30: Semi- or highly-supervised | Q30: Y | R30: 6 | S30: Biking, sitting, going up and down the stairs, standing, and walking | T30: N/A | U30: N/A | V30: CNN, ConvLSTM, GRU, Multi-task self supervised, autoencoder, simclr, cpc, enchanced cpc, vq cpc + lstm, vq + gru | W30: Y | X30: PyTorch | Y30: N | AA30: 2 | AB30: 0 (train), 50 (overlap for target) | AC30: 5-fold CV | AD30: F1 | AE30: Table 2, Table 8. Table 6 uses embeddings learned from CAPTURE-24 data. | AF30: N | AG30: N | AH30: Y | AI30: N | AJ30: N | AL30: N | AM30: Y | AP30: Y | AS30: =IF(AND(AP30="N", ISBLANK(AQ30)), "THIS", "")
B31: 76 | C31: Deep Learning Approach for Complex Activity Recognition using Heterogeneous Sensors from Wearable Device | D31: Narit Hnoohom | E31: https://doi.org/10.1109/RI2C51727.2021.9559773 | F31: Sep | G31: 2021 | H31: WISDM | I31: Y | K31: 20 | L31: N/A | M31: Android Wear 1.5 wearable (LG G Watch) | N31: 51 | O31: N/A | P31: N/A | Q31: Y | R31: 18 | S31: See Table 2 | T31: N/A | U31: N/A | V31: Att-BiLSTM and BiLSTM | W31: Y | X31: TensorFlow, Numpy, Pandas, and Scikit-Learn libraries | Y31: N | AA31: Multiple tested | AB31: Multiple tested | AC31: 10-fold CV | AD31: Accuracy, F1 | AE31: Table 4 | AF31: N | AG31: Y | AH31: N | AI31: N | AJ31: N | AL31: N | AM31: Y | AP31: N | AQ31: TTS | AS31: =IF(AND(AP31="N", ISBLANK(AQ31)), "THIS", "")
B32: 61 | C32: Activity Recognition with Wristband Based on Histogram and Bayesian Classifiers | D32: Yi-Cong Huang | E32: https://doi.org/10.1109/SIPROCESS.2019.8868412 | F32: Jul | G32: 2019 | H32: SC | I32: N/A | K32: N/A | L32: N/A | M32: N/A | N32: 8 | O32: N/A | P32: N/A | Q32: N/A | R32: 5 | S32: walking, office working, eating, sporting and resting | T32: N/A | U32: N/A | V32: Historgram with Bayesian classifier | W32: N | X32: N/A | Y32: Y | Z32: "Some useful motion features of these 4 seconds data blocks such as the energies, the time indices corresponding to the zero crossing points as well as the time indices of the crossing points of three different threshold values are extracted. Based on these motion feature vectors, a k means clustering algorithm [13] with the one norm operator as the criterion is performed for assigning the feature vectors [14]. Here, the feature vectors are classified into 9 clusters. Since the features are related to the energies and the time indices of the crossing points of different threshold values, the obtained cluster labels are related to the magnitudes of the motions." See Figure 3.4 | AA32: 20 s increment taken from 1 m, split into 4s windows for feautre extraction | AB32: 50 | AC32: N/A | AD32: Accuracy | AE32: Table 1, 2, 3 | AF32: Y | AG32: N | AH32: N | AI32: N | AJ32: N | AL32: N | AM32: N | AN32: IF | AP32: N | AQ32: DNA | AS32: =IF(AND(AP32="N", ISBLANK(AQ32)), "THIS", "")
B33: 37 | C33: A Comprehensive Analysis on Wearable Acceleration Sensors in Human Activity Recognition | D33: Majid Janidarmian | E33: https://doi.org/10.3390/s17030529 | F33: Feb | G33: 2017 | H33: Aggregated 14 datasets | I33: Y | K33: N/A | L33: N/A | M33: Listed for each dataset | N33: 228 across all datasets (not all have wrist data) | O33: 19-83 yo | P33: Variable across datasets | Q33: N | R33: 9 | S33: walking, running, jogging, cycling, standing, sitting, lying down, ascending and descending stairs | T33: N/A | U33: B | V33: 293 different classifiers (DT, discriminant analysis, SVM, KNN, ensemble methods, NB, and NN) | W33: Y | X33: N/A | Y33: Y | Z33: See Table 1 | AA33: Varies from 1 - 15 s in 1s intervals | AB33: 0 | AC33: LOSO CV | AD33: Accuracy | AE33: Fig. 5 | AF33: N | AG33: Y | AH33: N | AI33: N | AJ33: N | AL33: N | AM33: Y | AP33: Y | AS33: =IF(AND(AP33="N", ISBLANK(AQ33)), "THIS", "")
B34: 79 | C34: Topological persistence guided knowledge distillation for wearable sensor data | D34: Eun Som Jeon | E34: https://doi.org/10.1016/j.engappai.2023.107719 | F34: Apr | G34: 2024 | H34: GENEActiv | I34: Y | K34: 100 | L34: N/A | M34: GENEActiv | N34: N/A | O34: N/A | P34: Semi- or highly-supervised | Q34: N | R34: 14 | S34: See Figure 5 | T34: N/A | U34: N/A | V34: Teacher (CNN) / Student (WRN, wideresnet) model | W34: N | X34: Scikit-TDA (images) | Y34: N/A | AA34: 5 | AB34: 0 | AC34: SS. 70/30 | AD34: Accuracy | AE34: Table 2 and 3 | AF34: Y | AG34: N | AH34: Y | AI34: N | AJ34: N* (they say released upon acceptance) | AL34: N | AM34: N | AN34: IP | AP34: N | AQ34: TTS | AS34: =IF(AND(AP34="N", ISBLANK(AQ34)), "THIS", "")
B35: 105 | C35: Deep Neural Networks for Time Series Classification in Human Activity Recognition | D35: Shreehar Joshi | E35: https://doi.org/10.1109/IEMCON53756.2021.9623228 | F35: Oct | G35: 2021 | H35: WISDM | I35: Y | K35: 20 | L35: N/A | M35: N/A | N35: 51 | O35: N/A | P35: N/A | Q35: Y | R35: 13 (from 18) | S35: 1. Non-hand-oriented activities: a. Standing, b. Jogging, c. Stairs, d. Sitting, e. Walking 2. Hand-oriented activities: a. Typing, b. Writing, c. Brushing, d. Folding Clothes, e. Dribbling (Basketball), f. Playing (Catch), g. Eating (Pasta), h. Clapping "While the dataset initially consisted of raw data for 18 activities, those that were highly similar in nature (for instance, different variants of eating such as eating chips, sandwich, pasta, etc) are discarded and only 13 of them that are unique are used for this research." | T35: N/A | U35: N/A | V35: BiLSTM, CNN-LSTM, ConvLSTM, and CNN | W35: Y | X35: keras and sklearn | Y35: N | AA35: 4 | AB35: 50 | AC35: SS. 80/20 | AD35: Accuracy | AE35: Table 1, Fig. 5 | AF35: Y | AG35: Y | AH35: N | AI35: N | AJ35: N | AL35: N | AM35: Y | AP35: N | AQ35: TTS | AS35: =IF(AND(AP35="N", ISBLANK(AQ35)), "THIS", "")
B36: 43 | C36: Rich learning representations for human activity recognition: How to empower deep feature learning for biological time series | D36: Ria Kanjilal | E36: https://doi.org/10.1016/j.jbi.2022.104180 | F36: Oct | G36: 2022 | H36: Mannini | I36: Y | K36: 90 | L36: N/A | M36: Wocket | N36: 53 | O36: 33 "adults", 20 "youth" | P36: Semi- or highly-supervised | Q36: N | R36: 4 | S36: ambulation, cycling, other, sedentary | T36: N/A | U36: N/A | V36: 6 popular SotA models. Deep feed-forward neural network (DFNN), autoencoder deep feedforward neural network (AE-DFNN), one-dimensional convolutional neural network (1D-CNN), two-dimensional convolutional neural network (2D-CNN), recurrent neural network with long short-term memory (RNN-LSTM) and feature engineering using deep feed-forward neural network (FE-DFNN). Their novel model is a 2D CNN using a spectrogram as input. | W36: Y | X36: N/A | Y36: N | AA36: 30 | AB36: N/A | AC36: LOSO CV | AD36: Accuracy | AE36: Table 4 | AF36: N | AG36: Y | AH36: N | AI36: N | AJ36: N | AL36: N | AM36: N | AN36: IS | AP36: N | AQ36: ANR | AS36: =IF(AND(AP36="N", ISBLANK(AQ36)), "THIS", "")
B37: 58 | C37: A general framework for sensor-based human activity recognition | D37: Lukas Köping | E37: https://doi.org/10.1016/j.compbiomed.2017.12.025 | F37: Apr | G37: 2018 | H37: SC | I37: N/A | K37: 67 | L37: N/A | M37: Microdoft Band 2 | N37: 1 | O37: N/A | P37: Semi- or highly-supervised | Q37: N | R37: 11 | S37: 1. lying, 2. sitting, 3. standing, 4. walking, 5. bending, 6. getting up, 7. lying down, 8. putting a hand back, 9. sitting down, 10. standing up, and 11. stretching a hand. | T37: N/A | U37: N/A | V37: SVM (RBF kernel) | W37: N | X37: N/A | Y37: Y | Z37: N/A | AA37: 0.95 | AB37: 90 | AC37: N/A | AD37: Mean Average Precision (MAP) | AE37: Fig. 10, 11 | AF37: Y | AG37: Y | AH37: N | AI37: N | AJ37: Y* (only feature extraction, not full algorithm) | AK37: http://www.pr.iN/Aormatik.uni-siegen.de/en/ human-activity-recognition | AL37: N | AM37: Y | AP37: N | AQ37: DNA | AS37: =IF(AND(AP37="N", ISBLANK(AQ37)), "THIS", "")
B38: 62 | C38: A Deep Learning-Based Semantic Segmentation Model Using MCNN and Attention Layer for Human Activity Recognition | D38: Sang-hyub Lee | E38: https://doi.org/10.3390/s23042278 | F38: Feb | G38: 2023 | H38: SC | I38: N/A | K38: 15 | L38: N/A | M38: LIS2DS12TR, STMicroelectronics | N38: 8 | O38: All males, 20-40 yo | P38: Semi- or highly-supervised | Q38: Y | R38: 18 | S38: get-up, laying stand-up, picking, sitting, walking, walking-picking, walking-sitting, stand-up-walking, sitting-laying, get-up-stand-up, picking-walking,get-up-laying, laying-get-up, stand-up,=picking, stand-up-sitting, picking-sitting, sitting-stand-up | T38: N/A | U38: R | V38: Combinataions of GRU, RNN, LSTM, CNN, proposed model is MCNN with attention (16 evaluated in total) | W38: Y | X38: PyTorch | Y38: N | AA38: .6, 1.3, and 2.6 s (10, 20, and 40 samples) | AB38: 50 | AC38: LOSO CV | AD38: F1, Precision, Recall | AE38: Table 4 | AF38: Y | AG38: N | AH38: N | AI38: N | AJ38: N | AL38: N | AM38: Y | AP38: N | AQ38: DNA | AS38: =IF(AND(AP38="N", ISBLANK(AQ38)), "THIS", "")
B39: 115 | C39: Accelerometer Dense Trajectories for Activity Recognition and People Identification | D39: Roberto Leyva | E39: https://doi.org/10.1109/IWBF.2019.8739218 | F39: May | G39: 2019 | H39: SPHERE | I39: Y | K39: N/A | L39: N/A | M39: N/A | N39: N/A | O39: N/A | P39: N/A | Q39: N/A | R39: 10 (from 20) | S39: t_turn, t_straighten, t_stand_sit, t_stand_kneel, t_sit_stand, t_sit_lie, t_lie_sit, t_kneel_stand, t_bend, p_stand, p_squat, p_sit, p_lie, p_kneel, p_bent, a_walk, a_loadwalk, a_jump, a_descend, a_ascend | T39: N/A | U39: N/A | V39: DNN | W39: N | X39: MATLAB | Y39: Y | Z39: See Sec. III A and B | AA39: N/A | AB39: N/A | AC39: LOSO CV | AD39: Mean Average Precision (MAP) | AE39: Table 1 | AF39: N | AG39: N | AH39: Y | AI39: N | AJ39: N | AL39: N | AM39: N | AN39: IS | AP39: N | AQ39: ANR | AS39: =IF(AND(AP39="N", ISBLANK(AQ39)), "THIS", "")
B40: 112 | C40: Human activity recognition based on triaxial accelerometer using multi-feature weighted ensemble | D40: QingNan Li | E40: https://doi.org/10.1109/INDIN45582.2020.9442172 | F40: July | G40: 2020 | H40: SC | I40: N/A | K40: 200 | L40: N/A | M40: N/A | N40: 4 | O40: 2 F, 2 M | P40: N/A | Q40: N | R40: 8 | S40: shaking hands, waving hand, lying, walking, picking things up, bending over to pick things up, sit-down-stand-up, and open-close door | T40: N/A | U40: N/A | V40: KNN, attention LSTM, 1D CNN, ensemble method (theirs), CNN-LSTM | W40: Y | X40: N/A | Y40: Y | Z40: See Section IIC | AA40: 2 | AB40: 50 | AC40: SS. 60/12/28 | AD40: Accuracy | AE40: Fig. 4, Table 3 | AF40: Y | AG40: N | AH40: N | AI40: N | AJ40: N | AL40: N | AM40: N | AN40: IP | AP40: N | AQ40: DNA | AS40: =IF(AND(AP40="N", ISBLANK(AQ40)), "THIS", "")
...

Sheet Table_2
A1: Dataset (Raw Name) | B1: Count (by #) | D1: Dataset (Compiled) | E1: Count
A2: {=_xlfn.UNIQUE(All_Data!H3:'All_Data'!H180)} -> SC | B2: =COUNTIF(All_Data!H3:'All_Data'!H180, A2) -> 72 | D2: SC | E2: =B2+B12+B13+B23+B25+B34+B35+B38+B39+B40+B41 -> 82
A3: Bao + Intille | B3: =COUNTIF(All_Data!H4:'All_Data'!H181, A3) -> 1 | D3: Bao + Intille | E3: =B3+B20 -> 2
A4: HHAR | B4: =COUNTIF(All_Data!H5:'All_Data'!H182, A4) -> 7 | D4: HHAR | E4: =B4 -> 7
A5: PAMAP2 | B5: =COUNTIF(All_Data!H6:'All_Data'!H183, A5) -> 13 | D5: PAMAP2 | E5: =B5 -> 13
A6: RealWorld HAR | B6: =COUNTIF(All_Data!H7:'All_Data'!H184, A6) -> 5 | D6: RealWorld HAR | E6: =B34+B6 -> 6
A7: Extrasensory | B7: =COUNTIF(All_Data!H8:'All_Data'!H185, A7) -> 1 | D7: ExtraSensory | E7: =B7 -> 1
A8: WHARF | B8: =COUNTIF(All_Data!H9:'All_Data'!H186, A8) -> 6 | D8: WHARF | E8: =B8 -> 6
A9: MHEALTH | B9: =COUNTIF(All_Data!H10:'All_Data'!H187, A9) -> 6 | D9: WISDM | E9: =B10 -> 15
A10: WISDM | B10: =COUNTIF(All_Data!H11:'All_Data'!H188, A10) -> 15 | D10: CAPTURE-24 | E10: =B11 -> 1
A11: CAPTURE-24 | B11: =COUNTIF(All_Data!H12:'All_Data'!H189, A11) -> 1 | D11: Opportunity | E11: =B14 -> 4
A12: SC (Faculty of Sports) | B12: =COUNTIF(All_Data!H13:'All_Data'!H190, A12) -> 1 | D12: GENEActiv | E12: =B16 -> 1
A13: SC (JSI) | B13: =COUNTIF(All_Data!H14:'All_Data'!H191, A13) -> 1 | D13: Mannini | E13: =B17+B38 -> 4
A14: Opportunity | B14: =COUNTIF(All_Data!H15:'All_Data'!H192, A14) -> 4 | D14: SPHERE | E14: =B18 -> 2
A15: Aggregated 14 datasets | B15: =COUNTIF(All_Data!H16:'All_Data'!H193, A15) -> 1 | D15: UK BioBank | E15: =B19 -> 2
A16: GENEActiv | B16: =COUNTIF(All_Data!H17:'All_Data'!H194, A16) -> 1 | D16: DaLiAc | E16: =B21 -> 3
A17: Mannini | B17: =COUNTIF(All_Data!H18:'All_Data'!H195, A17) -> 3 | D17: ASTRI | E17: =B22 -> 1
A18: SPHERE | B18: =COUNTIF(All_Data!H19:'All_Data'!H196, A18) -> 2 | D18: Cleland | E18: =B24 -> 2
A19: UK BioBank | B19: =COUNTIF(All_Data!H20:'All_Data'!H197, A19) -> 2 | D19: DHA | E19: =B26 -> 3
A20: MIT (not cited) Bao + Intille | B20: =COUNTIF(All_Data!H21:'All_Data'!H198, A20) -> 1 | D20: IMSBD | E20: =B27 -> 1
A21: DaLiAc | B21: =COUNTIF(All_Data!H22:'All_Data'!H199, A21) -> 3 | D21: TwistAR | E21: =B28 -> 1
A22: ASTRI | B22: =COUNTIF(All_Data!H23:'All_Data'!H200, A22) -> 1 | D22: HMP | E22: =B29 -> 1
A23: SC (WSMC-HAR) | B23: =COUNTIF(All_Data!H24:'All_Data'!H201, A23) -> 2 | D23: GOTOv | E23: =B30 -> 1
A24: Cleland | B24: =COUNTIF(All_Data!H25:'All_Data'!H202, A24) -> 2 | D24: harAGE | E24: =B31 -> 1
A25: SC (ChoresXL) | B25: =COUNTIF(All_Data!H26:'All_Data'!H203, A25) -> 1 | D25: SHL | E25: =B32 -> 1
A26: DHA | B26: =COUNTIF(All_Data!H27:'All_Data'!H204, A26) -> 3 | D26: IMEC | E26: =B41 -> 1
A27: IM-Sporting Behaviors Dataset | B27: =COUNTIF(All_Data!H28:'All_Data'!H205, A27) -> 1 | D27: Oulu | E27: =B42 -> 1
A28: TWristAR | B28: =COUNTIF(All_Data!H29:'All_Data'!H206, A28) -> 1 | D28: DSADS | E28: =B43 -> 3
A29: HMP | B29: =COUNTIF(All_Data!H30:'All_Data'!H207, A29) -> 1 | D29: MHEALTH | E29: =B9 -> 6
A30: GOTOv | B30: =COUNTIF(All_Data!H31:'All_Data'!H208, A30) -> 1
A31: harAGE | B31: =COUNTIF(All_Data!H32:'All_Data'!H209, A31) -> 1
A32: SHL (Preview) | B32: =COUNTIF(All_Data!H33:'All_Data'!H210, A32) -> 1
A33: SC (DAAD) | B33: =COUNTIF(All_Data!H34:'All_Data'!H211, A33) -> 1
A34: SC (Realworld HAR) | B34: =COUNTIF(All_Data!H35:'All_Data'!H212, A34) -> 1
A35: 0 | B35: =COUNTIF(All_Data!H36:'All_Data'!H213, A35) -> 0
A36: SC (SelfBack) | B36: =COUNTIF(All_Data!H37:'All_Data'!H214, A36) -> 1
A37: SC (WEAR) | B37: =COUNTIF(All_Data!H38:'All_Data'!H215, A37) -> 1
A38: SC (Mannini) | B38: =COUNTIF(All_Data!H39:'All_Data'!H216, A38) -> 1
A39: SC (PAAWS) | B39: =COUNTIF(All_Data!H40:'All_Data'!H217, A39) -> 1
A40: SC? (Seems to be WISDM, not credited) | B40: =COUNTIF(All_Data!H41:'All_Data'!H218, A40) -> 1
...

Sheet Table_3
A1: Contribution Area | B1: Article ID | C1: Title | D1: First Author | E1: Reproducible | F1: Replicable | G1: Weights | H1: Algorithms | I1: Data | J1: Cross DS | K1: Mult DS | L1: Classwise | M1: Baseline | N1: Single Split | O1: k-fold CV | P1: LOSO CV | Q1: R | R1: ND | S1: L | T1: D | U1: B | V1: 10+ | W1: 9 6 to 9 | X1: 2 to 5
A2: Algorithmic Changes (e.g., architecture or preprocessing) | B2: 66 | C2: A Hybrid Solution for Human Activity Recognition: Application to Wrist-Worn Accelerometry | D2: Manuel Abbas | L2: \gcheck | M2: \gcheck | O2: \gcheck | X2: \gcheck
B3: 94 | C3: Characterizing Peaks in Acceleration Signals–Application to Physical Activity Detection Using Wearable Sensors | D3: Manuel Abbas | F3: \gcheck | L3: \gcheck | M3: \gcheck | O3: \gcheck | P3: \gcheck | X3: \gcheck
B4: 5 | C4: Daily living activity recognition based on statistical feature quality group selection | D4: Oresti Banos | I4: \gcheck | K4: \ycheck | M4: \gcheck | O4: \gcheck | X4: \gcheck
B5: 24 | C5: Significant Features for Human Activity Recognition Using Tri-Axial Accelerometers | D5: Mohamed Bennasar | I5: \gcheck | K5: \gcheck | M5: \gcheck | O5: \gcheck | T5: \gcheck | V5: \gcheck | W5: \gcheck
B6: 25 | C6: Improving Deep Learning for HAR with Shallow LSTMs | D6: Marius Bock | E6: \gcheck | F6: \gcheck | G6: \ycheck | H6: \gcheck | I6: \gcheck | K6: \gcheck | M6: \gcheck | P6: \gcheck | W6: \gcheck
B7: 151 | C7: Handling heterogeneity in Human Activity Recognition data by a compact Long Short Term Memory based deep learning approach | D7: Ahmed Cemiloglu | I7: \gcheck | L7: \gcheck | M7: \gcheck | N7: \gcheck | U7: \gcheck | W7: \gcheck
B8: 59 | C8: Activity classification using a single wrist-worn accelerometer | D8: Saisakul Chernbumroong | M8: \gcheck | O8: \gcheck | R8: \gcheck | X8: \gcheck
B9: 39 | C9: Temporal Alignment Improves Feature Quality: An Experiment on Activity Recognition with Accelerometer Data | D9: Hongjun Choi | L9: \gcheck | P9: \gcheck | R9: \gcheck | W9: \gcheck
B10: 132 | C10: Ensemble Methods for Classification of Physical Activities from Wrist Accelerometry | D10: Aok Kumar Chowdhury | E10: \gcheck | F10: \gcheck | H10: \gcheck | I10: \gcheck | K10: \gcheck | L10: \gcheck | M10: \gcheck | P10: \gcheck | R10: \gcheck | T10: \gcheck | W10: \gcheck | X10: \gcheck
B11: 155 | C11: Situation identification in smart wearable computing systems based on machine learning and Context Space Theory | D11: Giuseppe D'Aniello | E11: \gcheck | F11: \gcheck | H11: \gcheck | I11: \gcheck | L11: \ycheck | M11: \gcheck | O11: \gcheck | X11: \gcheck
B12: 83 | C12: Comparing Supervised Learning Techniques on the Task of Physical Activity Recognition | D12: Anthony Dalton | F12: \gcheck | M12: \gcheck | P12: \gcheck | T12: \gcheck | V12: \gcheck
B13: 99 | C13: Recognition of Human Behavior for Assisted Living Using Dictionary Learning Approach | D13: Pubali De | I13: \gcheck | L13: \gcheck | M13: \gcheck | N13: \gcheck | W13: \gcheck
B14: 46 | C14: Multi-Criteria Analysis of Sensor Reliability for Wearable Human Activity Recognition | D14: Yilin Dong | I14: \gcheck | L14: \gcheck | M14: \gcheck | O14: \gcheck | Q14: \gcheck | V14: \gcheck
B15: 87 | C15: Temporal-channel convolution with self-attention network for human activity recognition using wearable sensors | D15: Ehab Essa | I15: \gcheck | K15: \gcheck | L15: \gcheck | M15: \gcheck | P15: \gcheck | Q15: \gcheck | V15: \gcheck
B16: 13 | C16: Matched Filter Interpretation of CNN Classifiers with Application to HAR | D16: Mohammed M. Farag | F16: \gcheck | I16: \gcheck | K16: \gcheck | L16: \gcheck | N16: \gcheck | W16: \gcheck
B17: 14 | C17: AccNet24: A deep learning framework for classifying 24-hour activity behaviours from wrist-worn accelerometer data under free-living environments | D17: Vahid Farrahi | I17: \gcheck | L17: \gcheck | M17: \gcheck | N17: \gcheck | X17: \gcheck
B18: 85 | C18: A Comparative Study on Fitness Activity Recognition | D18: Igor Lopes de Faria | M18: \gcheck | O18: \gcheck | X18: \gcheck
B19: 7 | C19: Improving Activity Recognition while Reducing Misclassification of Unknown Activities | D19: Andrea Fasciglione | N19: \gcheck | T19: \gcheck | V19: \gcheck
B20: 152 | C20: Modelling time-series data generation with diffusion models for triaxial data | D20: Francisco M. Garcia-Moreno | E20: \gcheck | F20: \gcheck | H20: \gcheck | I20: \gcheck | M20: \gcheck | P20: \gcheck | X20: \gcheck
B21: 15 | C21: How Accurately Can Your Wrist Device Recognize Daily Activities and Detect Falls? | D21: Martin Gjoreski | I21: \ycheck | K21: \gcheck | L21: \gcheck | M21: \gcheck | P21: \gcheck | Q21: \gcheck | U21: \gcheck | V21: \gcheck | X21: \gcheck
B22: 31 | C22: Reducing the Impact of Sensor Orientation Variability in Human Activity Recognition Using a Consistent Reference System | D22: Manuel Gil-Martín | F22: \gcheck | I22: \gcheck | K22: \gcheck | O22: \gcheck | P22: \gcheck | T22: \gcheck | V22: \gcheck
B23: 88 | C23: Towards Learning Discrete Representations via Self-Supervision for Wearables-Based Human Activity Recognition | D23: Harish Haresamudram | E23: \gcheck | F23: \gcheck | I23: \gcheck | K23: \gcheck | M23: \gcheck | O23: \gcheck | W23: \gcheck
B24: 76 | C24: Deep Learning Approach for Complex Activity Recognition using Heterogeneous Sensors from Wearable Device | D24: Narit Hnoohom | F24: \gcheck | I24: \gcheck | M24: \gcheck | O24: \gcheck | V24: \gcheck
B25: 61 | C25: Activity Recognition with Wristband Based on Histogram and Bayesian Classifiers | D25: Yi-Cong Huang | L25: \gcheck | X25: \gcheck
B26: 37 | C26: A Comprehensive Analysis on Wearable Acceleration Sensors in Human Activity Recognition | D26: Majid Janidarmian | E26: \gcheck | F26: \gcheck | I26: \gcheck | M26: \gcheck | P26: \gcheck | U26: \gcheck | W26: \gcheck
B27: 79 | C27: Topological persistence guided knowledge distillation for wearable sensor data | D27: Eun Som Jeon | H27: \ycheck | I27: \gcheck | K27: \gcheck | L27: \gcheck | N27: \gcheck | V27: \gcheck
B28: 105 | C28: Deep Neural Networks for Time Series Classification in Human Activity Recognition | D28: Shreehar Joshi | F28: \gcheck | I28: \gcheck | L28: \gcheck | M28: \gcheck | N28: \gcheck | V28: \gcheck
B29: 43 | C29: Rich learning representations for human activity recognition: How to empower deep feature learning for biological time series | D29: Ria Kanjilal | I29: \gcheck | M29: \gcheck | P29: \gcheck | X29: \gcheck
B30: 58 | C30: A general framework for sensor-based human activity recognition | D30: Lukas Köping | F30: \gcheck | H30: \ycheck | L30: \gcheck | V30: \gcheck
B31: 62 | C31: A Deep Learning-Based Semantic Segmentation Model Using MCNN and Attention Layer for Human Activity Recognition | D31: Sang-hyub Lee | F31: \gcheck | L31: \gcheck | M31: \gcheck | P31: \gcheck | Q31: \gcheck | V31: \gcheck
B32: 115 | C32: Accelerometer Dense Trajectories for Activity Recognition and People Identification | D32: Roberto Leyva | I32: \gcheck | K32: \gcheck | P32: \gcheck | V32: \gcheck
B33: 112 | C33: Human activity recognition based on triaxial accelerometer using multi-feature weighted ensemble | D33: QingNan Li | L33: \gcheck | M33: \gcheck | N33: \gcheck | W33: \gcheck
B34: 103 | C34: Human Activity Recognition in Free Living Using a Wearable Sensor: A Two-Stage Approach | D34: Tianhui Li | K34: \gcheck | N34: \gcheck | R34: \gcheck | X34: \gcheck
B35: 142 | C35: Frequency-Aware Masked Autoencoders for Human Activity Recognition using Accelerometers | D35: Niels R. Lorenzen | F35: \gcheck | I35: \gcheck | L35: \gcheck | N35: \gcheck | W35: \gcheck
B36: 98 | C36: Research on human activity recognition based on active learning | D36: Rong Liu | I36: \gcheck | N36: \gcheck | T36: \gcheck | V36: \gcheck
B37: 102 | C37: MFE-HAR: multiscale feature engineering for human activity recognitionusing wearable sensors | D37: Jianchao Lu | I37: \gcheck | K37: \gcheck | L37: \gcheck | M37: \gcheck | Q37: \gcheck | V37: \gcheck
B38: 51 | C38: Robust Single Accelerometer-Based Activity Recognition Using Modified Recurrence Plot | D38: Jianjie Lu | E38: \gcheck | F38: \gcheck | G38: \gcheck | H38: \gcheck | I38: \gcheck | K38: \gcheck | L38: \gcheck | M38: \gcheck | N38: \gcheck | W38: \gcheck | X38: \gcheck
B39: 150 | C39: A two-stage multi-branch fusion model for human activity recognition based on sensor data transformed by gramian angular difference field | D39: Limeng Lu | F39: \gcheck | I39: \gcheck | K39: \gcheck | L39: \gcheck | M39: \ycheck | X39: \gcheck
B40: 97 | C40: Wearable Computing for Internet of Things: A Discriminant Approach for Human Activity Recognition | D40: Wei Lu | I40: \gcheck | K40: \gcheck | M40: \gcheck | N40: \gcheck | Q40: \gcheck | V40: \gcheck
...

Sheet Fig_3
A1: Meta Data | E1: Missing Atrribute
A2: Contribution Area | B2: Article ID | C2: Title | D2: First Author | E2: Device | F2: Frequency | G2: Range | H2: Definitions | I2: Wrist | J2: Demographics | K2: n | L2: Length | M2: Overlap | N2: Data | O2: Libraries | P2: TTS
A3: Algorithm Improvement (e.g., architecture or preprocessing) | B3: 66 | C3: A Hybrid Solution for Human Activity Recognition: Application to Wrist-Worn Accelerometry | D3: Manuel Abbas | I3: N | N3: N | O3: N
B4: 94 | C4: Characterizing Peaks in Acceleration Signals–Application to Physical Activity Detection Using Wearable Sensors | D4: Manuel Abbas | I4: N | N4: N | O4: N
B5: 5 | C5: Daily living activity recognition based on statistical feature quality group selection | D5: Oresti Banos | E5: N | G5: N | H5: N | I5: N | J5: N | K5: N | L5: N | M5: N | O5: N
B6: 24 | C6: Significant Features for Human Activity Recognition Using Tri-Axial Accelerometers | D6: Mohamed Bennasar | E6: N | G6: N | H6: N | I6: N | M6: N
B7: 25 | C7: Improving Deep Learning for HAR with Shallow LSTMs | D7: Marius Bock | E7: N | G7: N | H7: N | I7: N | J7: N
B8: 151 | C8: Handling heterogeneity in Human Activity Recognition data by a compact Long Short Term Memory based deep learning approach | D8: Ahmed Cemiloglu | G8: N | H8: N | M8: N
B9: 59 | C9: Activity classification using a single wrist-worn accelerometer | D9: Saisakul Chernbumroong | N9: N
B10: 39 | C10: Temporal Alignment Improves Feature Quality: An Experiment on Activity Recognition with Accelerometer Data | D10: Hongjun Choi | F10: N | G10: N | H10: N | M10: N | N10: N
B11: 132 | C11: Ensemble Methods for Classification of Physical Activities from Wrist Accelerometry | D11: Aok Kumar Chowdhury | H11: N
B12: 155 | C12: Situation identification in smart wearable computing systems based on machine learning and Context Space Theory | D12: Giuseppe D'Aniello | E12: N | G12: N | I12: N | J12: N
B13: 83 | C13: Comparing Supervised Learning Techniques on the Task of Physical Activity Recognition | D13: Anthony Dalton | E13: N | N13: N
B14: 99 | C14: Recognition of Human Behavior for Assisted Living Using Dictionary Learning Approach | D14: Pubali De | E14: N | H14: N | I14: N | L14: N | M14: N | O14: N
B15: 46 | C15: Multi-Criteria Analysis of Sensor Reliability for Wearable Human Activity Recognition | D15: Yilin Dong | E15: N | G15: N | H15: N | L15: N | M15: N
B16: 87 | C16: Temporal-channel convolution with self-attention network for human activity recognition using wearable sensors | D16: Ehab Essa | E16: N | G16: N | H16: N | J16: N | L16: N | M16: N
B17: 13 | C17: Matched Filter Interpretation of CNN Classifiers with Application to HAR | D17: Mohammed M. Farag | E17: N | G17: N | H17: N | I17: N | J17: N
B18: 14 | C18: AccNet24: A deep learning framework for classifying 24-hour activity behaviours from wrist-worn accelerometer data under free-living environments | D18: Vahid Farrahi | G18: N | I18: N
B19: 85 | C19: A Comparative Study on Fitness Activity Recognition | D19: Igor Lopes de Faria | E19: N | F19: N | G19: N | I19: N | N19: N
B20: 7 | C20: Improving Activity Recognition while Reducing Misclassification of Unknown Activities | D20: Andrea Fasciglione | E20: N | G20: N | H20: N | L20: N | M20: N | N20: N | O20: N
B21: 152 | C21: Modelling time-series data generation with diffusion models for triaxial data | D21: Francisco M. Garcia-Moreno | E21: N | G21: N | H21: N | I21: N | J21: N | O21: N
B22: 15 | C22: How Accurately Can Your Wrist Device Recognize Daily Activities and Detect Falls? | D22: Martin Gjoreski | G22: N | H22: N | J22: N | O22: N
B23: 31 | C23: Reducing the Impact of Sensor Orientation Variability in Human Activity Recognition Using a Consistent Reference System | D23: Manuel Gil-Martín | E23: N | G23: N | H23: N | J23: N | O23: N
B24: 88 | C24: Towards Learning Discrete Representations via Self-Supervision for Wearables-Based Human Activity Recognition | D24: Harish Haresamudram | G24: N | H24: N | I24: N | J24: N
B25: 76 | C25: Deep Learning Approach for Complex Activity Recognition using Heterogeneous Sensors from Wearable Device | D25: Narit Hnoohom | G25: N | H25: N | I25: N | J25: N
B26: 61 | C26: Activity Recognition with Wristband Based on Histogram and Bayesian Classifiers | D26: Yi-Cong Huang | E26: N | F26: N | G26: N | H26: N | I26: N | J26: N | N26: N | O26: N | P26: N
B27: 37 | C27: A Comprehensive Analysis on Wearable Acceleration Sensors in Human Activity Recognition | D27: Majid Janidarmian | F27: N | G27: N | H27: N | O27: N
B28: 79 | C28: Topological persistence guided knowledge distillation for wearable sensor data | D28: Eun Som Jeon | G28: N | H28: N | I28: N | J28: N | K28: N
B29: 105 | C29: Deep Neural Networks for Time Series Classification in Human Activity Recognition | D29: Shreehar Joshi | E29: N | G29: N | H29: N | I29: N | J29: N
B30: 43 | C30: Rich learning representations for human activity recognition: How to empower deep feature learning for biological time series | D30: Ria Kanjilal | G30: N | H30: N | I30: N | M30: N | O30: N
B31: 58 | C31: A general framework for sensor-based human activity recognition | D31: Lukas Köping | G31: N | H31: N | I31: N | J31: N | N31: N | O31: N | P31: N
B32: 62 | C32: A Deep Learning-Based Semantic Segmentation Model Using MCNN and Attention Layer for Human Activity Recognition | D32: Sang-hyub Lee | G32: N | H32: N | N32: N
B33: 115 | C33: Accelerometer Dense Trajectories for Activity Recognition and People Identification | D33: Roberto Leyva | E33: N | F33: N | G33: N | H33: N | I33: N | J33: N | K33: N | L33: N | M33: N
B34: 112 | C34: Human activity recognition based on triaxial accelerometer using multi-feature weighted ensemble | D34: QingNan Li | E34: N | G34: N | H34: N | I34: N | N34: N | O34: N
B35: 103 | C35: Human Activity Recognition in Free Living Using a Wearable Sensor: A Two-Stage Approach | D35: Tianhui Li | E35: N | G35: N | H35: N | N35: N
B36: 142 | C36: Frequency-Aware Masked Autoencoders for Human Activity Recognition using Accelerometers | D36: Niels R. Lorenzen | G36: N | H36: N | I36: N | J36: N | O36: N
B37: 98 | C37: Research on human activity recognition based on active learning | D37: Rong Liu | E37: N | F37: N | G37: N | H37: N | J37: N | K37: N | L37: N | M37: N | O37: N
B38: 102 | C38: MFE-HAR: multiscale feature engineering for human activity recognitionusing wearable sensors | D38: Jianchao Lu | E38: N | G38: N | H38: N | J38: N | P38: N
B39: 51 | C39: Robust Single Accelerometer-Based Activity Recognition Using Modified Recurrence Plot | D39: Jianjie Lu | E39: N | G39: N | H39: N | I39: N | J39: N | M39: N | O39: N
B40: 150 | C40: A two-stage multi-branch fusion model for human activity recognition based on sensor data transformed by gramian angular difference field | D40: Limeng Lu | E40: N | H40: N | I40: N | P40: N
...
