Workbook

Sheet Screening_Results_Raw
A1: RAW SCREENING RESULTS
A2: TITLE | B2: DOI | C2: STAGE | D2: REASON
A3: [-25]A Similarity Analysis of Audio Signal to Develop a Human Activity Recognition Using Similarity Networks | B3: 10.3390/s17112688 | C3: TITLE | D3: NON-WEARABLE
A4: [Copyright notice] | B4: 10.1109/TENCON.2011.6128997 | C4: TITLE | D4: NON-ARTICLE
A5: [Copyright notice] | B5: 10.1109/BSN.2010.3 | C5: TITLE | D5: NON-ARTICLE
A6: [Development of a wearable electrocardiogram monitor with recognition of physical activity scene] | B6: PMID: 23198439 | C6: TITLE | D6: IRRELEVANT
A7: [Display of glucose oxidase on Bacillus subtilis spore surface and preparation for enzyme electrode] | B7: 10.13345/j.cjb.200042 | C7: TITLE | D7: OOS CT
A8: [Front cover] | B8: 10.1109/CIST.2016.7804841 | C8: TITLE | D8: NON-ARTICLE
A9: [MARS] a real time motion capture and muscle fatigue monitoring tool | B9: 10.1145/2426656.2426721 | C9: TITLE | D9: IRRELEVANT
A10: [Poster] You Only Sense Once: Unified Localization and ActivityRecognition of Multiple Persons | B10: 10.1145/3643832.3661447 | C10: TITLE | D10: NON-ARTICLE
A11: [Title page i] | B11: 10.1109/BSN.2009.1 | C11: TITLE | D11: NON-ARTICLE
A12: [Title page] | B12: 10.1109/ROMAN.2012.6343904 | C12: TITLE | D12: NON-ARTICLE
A13: [Title page] | B13: https://doi.org/10.1145/2047478.2047482 | C13: TITLE | D13: NON-ARTICLE
... A158: A General Framework for Making Context-Recognition Systems More Energy Efficient | B158: 10.3390/s21030766 | C158: TITLE | D158: IRRELEVANT
A159: A geometric interpretation of non-target-normalized maximum cross-channelcorrelation for vocal activity detection in meetings | C159: TITLE | D159: IRRELEVANT
A160: A Ground Truth System for Radar Measurements of Humans | C160: TITLE | D160: NON-WEARABLE
A161: A GRU-Based Model for Detecting Common Accidents of Construction Workers | B161: 10.3390/s24020672 | C161: TITLE | D161: IRRELEVANT
A162: A health monitoring system based on flexible triboelectric sensors for intelligence medical internet of things and its applications in virtual reality | B162: https://doi.org/10.1016/j.nanoen.2023.108984 | C162: TITLE | D162: IRRELEVANT
A163: A Hierarchical Approach in Food and Drink Intake Recognition UsingWearable Inertial Sensors | B163: 10.1145/3197768.3201542 | C163: TITLE | D163: OOS CT
A164: A Hierarchical Deep Fusion Framework for Egocentric Activity Recognition Using a Wearable Hybrid Sensor System | B164: 10.3390/s19030546 | C164: TITLE | D164: NON-WEARABLE
A165: A Hierarchical Deep Fusion Framework for Egocentric Activity Recognition using a Wearable Hybrid Sensor System | B165: 10.3390/s19030546 | C165: TITLE | D165: NOT WAO
A166: A hierarchical model for recognizing alarming states in a batteryless sensor alarm intervention for preventing falls in older people | B166: https://doi.org/10.1016/j.pmcj.2017.04.002 | C166: TITLE | D166: OOS CT
A167: A Hierarchy-Based System for Recognizing Customer Activity in Retail Environments | B167: 10.3390/s21144712 | C167: TITLE | D167: IRRELEVANT
A168: A high sensitivity background eliminated fluorescence sensing platform for hyaluronidase activity detection based on Si QDs/HA--FeOOH nanoassembly | B168: https://doi.org/10.1016/j.bios.2019.111928 | C168: TITLE | D168: IRRELEVANT
A169: A high sensitivity background eliminated fluorescence sensing platform for hyaluronidase activity detection based on Si QDs/HA-Œ¥-FeOOH nanoassembly | B169: 10.1016/j.bios.2019.111928 | C169: TITLE | D169: OOS CT
A170: A highly sensitive, eco-friendly electrochemical assay for alkaline phosphatase activity based on a photoATRP signal amplification strategy | B170: https://doi.org/10.1016/j.talanta.2022.123775 | C170: TITLE | D170: IRRELEVANT
A171: A Human Activity Recognition Scheme Using Mobile Smartphones Based on Varying Orientations and Positions | B171: 10.1109/JSEN.2024.3380076 | C171: TITLE | D171: NOT WAO
A172: A Human Activity Recognition System Using Skeleton Data from RGBD Sensors | B172: 10.1155/2016/4351435 | C172: TITLE | D172: NON-WEARABLE
A173: A human activity recognition-aware framework using multi-modal sensor data fusion | B173: 10.1109/ICCE.2018.8326109 | C173: TITLE | D173: NOT WAO
A174: A human morning routine dataset | C174: TITLE | D174: IRRELEVANT
A175: A Hybrid Accuracy- and Energy-Aware Human Activity Recognition Model in IoT Environment | B175: 10.1109/TSUSC.2022.3209086 | C175: TITLE | D175: NON-WEARABLE
A176: A Hybrid Attention-Based Deep Neural Network for Simultaneous Multi-Sensor Pruning and Human Activity Recognition | B176: 10.1109/JIOT.2022.3196170 | C176: TITLE | D176: NOT WAO
A177: A hybrid classification approach to improving location accuracy in a Bluetooth-based room localisation system | B177: 10.1109/ICMLC.2010.5581038 | C177: TITLE | D177: NON-WEARABLE
A178: A hybrid deep approach to recognizing student activity and monitoring health physique based on accelerometer data from smartphones | B178: 10.1038/s41598-024-63934-8 | C178: TITLE | D178: NOT WAO
A179: A hybrid deep convolutional and recurrent neural network for complex activity recognition using multimodal sensors | B179: https://doi.org/10.1016/j.neucom.2019.06.051 | C179: TITLE | D179: NOT WAO
A180: A Hybrid Deep Learning Model for Human Activity Recognition Using Multimodal Body Sensing Data | B180: 10.1109/ACCESS.2019.2927134 | C180: TITLE | D180: NOT WAO
A181: A Hybrid Deep Neural Network with Attention Mechanism for Human Activity Recognition Based on Smartphone Sensors | B181: 10.1109/InCIT60207.2023.10413113 | C181: TITLE | D181: NOT WAO
A182: A Hybrid Indoor Altimetry Based on Barometer and UWB | B182: 10.3390/s23094180 | C182: TITLE | D182: IRRELEVANT
A183: A Hybrid Kinematic-Acoustic System for Automated Activity Detection of Construction Equipment | B183: 10.3390/s19194286 | C183: TITLE | D183: OOS CT
A184: A Hybrid Protection Scheme for the Gait Analysis in Early Dementia Recognition | B184: 10.3390/s24010024 | C184: TITLE | D184: IRRELEVANT
...

Sheet PRISMA_Diagram
A1: PRISMA DIAGRAM | I1: Sanity Check | M1: Aggregate Stats | Q1: Pulled from DB Breakdown
A2: TOTAL | B2: 7822 | I2: TOTAL | J2: =6466+1356 -> 7822 | M2: TOTAL FROM DB | N2: PRE AUG 2024 | O2: 7302 | R2: Pre Aug 2024 | S2: Post Aug 2024 | T2: TOTAL
A3: TITLE | B3: IRRELEVANT | C3: =COUNTIFS(Screening_Results_Raw!C:C,"TITLE",Screening_Results_Raw!D:D,B3) -> 2157 | E3: Codes: | F3: =SUM(C3:C10) -> 4792 | I3: IRRELEVANT | J3: =COUNTIF(Screening_Results_Raw!D:D,I3) -> 2324 | M3: 8917 | N3: POST AUG 2024 | O3: 1615 | Q3: IEEE | R3: 2942 | S3: 803 | T3: =SUM(R3:S3) -> 3745
B4: NON-ARTICLE | C4: =COUNTIFS(Screening_Results_Raw!C:C,"TITLE",Screening_Results_Raw!D:D,B4) -> 88 | E4: Sum: | F4: =COUNTIF(Screening_Results_Raw!C:C, "TITLE") -> 4792 | I4: NON-ARTICLE | J4: =COUNTIF(Screening_Results_Raw!D:D,I4) -> 160 | Q4: ACM DL | R4: 1019 | S4: 189 | T4: =SUM(R4:S4) -> 1208
B5: SURVEY/REVIEW | C5: =COUNTIFS(Screening_Results_Raw!C:C,"TITLE",Screening_Results_Raw!D:D,B5) -> 156 | I5: SURVEY/REVIEW | J5: =COUNTIF(Screening_Results_Raw!D:D,I5) -> 190 | M5: DUPLICATES | N5: PRE AUG 2024 | O5: 836 | Q5: PubMed | R5: 1562 | S5: 179 | T5: =SUM(R5:S5) -> 1741
B6: OOS CT | C6: =COUNTIFS(Screening_Results_Raw!C:C,"TITLE",Screening_Results_Raw!D:D,B6) -> 773 | I6: OOS CT | J6: =COUNTIF(Screening_Results_Raw!D:D,I6) -> 956 | M6: 1095 | N6: POST AUG 2024 | O6: 259 | Q6: SD/Elsevier | R6: 837 | S6: 342 | T6: =SUM(R6:S6) -> 1179
B7: NON-WEARABLE | C7: =COUNTIFS(Screening_Results_Raw!C:C,"TITLE",Screening_Results_Raw!D:D,B7) -> 724 | I7: NON-WEARABLE | J7: =COUNTIF(Screening_Results_Raw!D:D,I7) -> 1109 | Q7: Sensors | R7: 942 | S7: 102 | T7: =SUM(R7:S7) -> 1044
B8: NOT WAO | C8: =COUNTIFS(Screening_Results_Raw!C:C,"TITLE",Screening_Results_Raw!D:D,B8) -> 892 | I8: NOT WAO | J8: =COUNTIF(Screening_Results_Raw!D:D,I8) -> 2701 | M8: SCREENED | N8: PRE AUG 2024 | O8: 6466 | Q8: TOTAL | R8: =SUM(R3:R7) -> 7302 | S8: =SUM(S3:S7) -> 1615 | T8: =SUM(T3:T7) -> 8917
B9: INSUFFICIENT DETAIL | C9: =COUNTIFS(Screening_Results_Raw!C:C,"TITLE",Screening_Results_Raw!D:D,B9) -> 0 | I9: INSUFFICIENT DETAIL | J9: =COUNTIF(Screening_Results_Raw!D:D,I9) -> 214 | K9: Total Excluded | M9: 7822 | N9: POST AUG 2024 | O9: 1356
B10: NOT AVAILABLE | C10: =COUNTIFS(Screening_Results_Raw!C:C,"TITLE",Screening_Results_Raw!D:D,B10) -> 2 | E10: TO ABSTRACT | F10: =B2-F3 -> 3030 | I10: NOT AVAILABLE | J10: =COUNTIF(Screening_Results_Raw!D:D,I10) -> 14 | K10: =J12-J11 -> 7668
I11: INCLUDED | J11: =B30 -> 154 | M11: INCLUDED | N11: PRE AUG 2024 | O11: 138
A12: ABSTRACT | B12: IRRELEVANT | C12: =COUNTIFS(Screening_Results_Raw!C:C,$A$12,Screening_Results_Raw!D:D,B12) -> 72 | E12: Codes: | F12: =SUM(C12:C19) -> 940 | J12: =SUM(J3:J11) -> 7822 | M12: 154 | N12: POST AUG 2024 | O12: 18
B13: NON-ARTICLE | C13: =COUNTIFS(Screening_Results_Raw!C:C,$A$12,Screening_Results_Raw!D:D,B13) -> 15 | E13: Sum: | F13: =COUNTIF(Screening_Results_Raw!C:C, "ABSTRACT") -> 940
B14: SURVEY/REVIEW | C14: =COUNTIFS(Screening_Results_Raw!C:C,$A$12,Screening_Results_Raw!D:D,B14) -> 26
B15: OOS CT | C15: =COUNTIFS(Screening_Results_Raw!C:C,$A$12,Screening_Results_Raw!D:D,B15) -> 62
B16: NON-WEARABLE | C16: =COUNTIFS(Screening_Results_Raw!C:C,$A$12,Screening_Results_Raw!D:D,B16) -> 252
B17: NOT WAO | C17: =COUNTIFS(Screening_Results_Raw!C:C,$A$12,Screening_Results_Raw!D:D,B17) -> 511
B18: INSUFFICIENT DETAIL | C18: =COUNTIFS(Screening_Results_Raw!C:C,$A$12,Screening_Results_Raw!D:D,B18) -> 0
B19: NOT AVAILABLE | C19: =COUNTIFS(Screening_Results_Raw!C:C,$A$12,Screening_Results_Raw!D:D,B19) -> 2 | E19: TO FULL TEXT | F19: =F10-F12 -> 2090
A21: FULL TEXT | B21: IRRELEVANT | C21: =COUNTIFS(Screening_Results_Raw!C:C,$A$21,Screening_Results_Raw!D:D,B21) -> 95 | E21: Codes: | F21: =SUM(C21:C28) -> 1936
B22: NON-ARTICLE | C22: =COUNTIFS(Screening_Results_Raw!C:C,$A$21,Screening_Results_Raw!D:D,B22) -> 57 | E22: Sum: | F22: =COUNTIF(Screening_Results_Raw!C:C, "FULL TEXT") -> 1936
B23: SURVEY/REVIEW | C23: =COUNTIFS(Screening_Results_Raw!C:C,$A$21,Screening_Results_Raw!D:D,B23) -> 8
B24: OOS CT | C24: =COUNTIFS(Screening_Results_Raw!C:C,$A$21,Screening_Results_Raw!D:D,B24) -> 121
B25: NON-WEARABLE | C25: =COUNTIFS(Screening_Results_Raw!C:C,$A$21,Screening_Results_Raw!D:D,B25) -> 133
B26: NOT WAO | C26: =COUNTIFS(Screening_Results_Raw!C:C,$A$21,Screening_Results_Raw!D:D,B26) -> 1298
B27: INSUFFICIENT DETAIL | C27: =COUNTIFS(Screening_Results_Raw!C:C,$A$21,Screening_Results_Raw!D:D,B27) -> 214
B28: NOT AVAILABLE | C28: =COUNTIFS(Screening_Results_Raw!C:C,$A$21,Screening_Results_Raw!D:D,B28) -> 10 | E28: TO INC | F28: =F19-F21 -> 154
A30: INCLUDED | B30: =138+16 -> 154
